<?xml version="1.0" encoding="utf-8"?>
<!-- This URDF was automatically created by SolidWorks to URDF Exporter! Originally created by Stephen Brawner (brawner@gmail.com) 
     Commit Version: 1.6.0-4-g7f85cfe  Build Version: 1.6.7995.38578
     For more information, please see http://wiki.ros.org/sw_urdf_exporter -->
<robot
  name="bparm_5_1">
  <link
    name="base_link">
    <inertial>
      <origin
        xyz="0.000147714993379983 3.86437548627327E-11 0.0344335444558568"
        rpy="0 0 0" />
      <mass
        value="0.09275682784384" />
      <inertia
        ixx="0.000171517453339657"
        ixy="6.62437339286854E-10"
        ixz="1.19244230968858E-07"
        iyy="3.61830561224153E-05"
        iyz="1.12679946344087E-13"
        izz="0.000179050068336717" />
    </inertial>
    <visual>
      <origin
        xyz="0 0 0"
        rpy="0 0 0" />
      <geometry>
        <mesh
          filename="package://bparm_5_1_description/meshes/base_link.STL" />
      </geometry>
      <material
        name="">
        <color
          rgba="1 1 1 1" />
      </material>
    </visual>
    <collision>
      <origin
        xyz="0 0 0"
        rpy="0 0 0" />
      <geometry>
        <mesh
          filename="package://bparm_5_1_description/meshes/base_link.STL" />
      </geometry>
    </collision>
  </link>
  <link
    name="link1">
    <inertial>
      <origin
        xyz="-3.60001792265585E-09 0.0224429410533554 2.86723154053481E-05"
        rpy="0 0 0" />
      <mass
        value="0.242703771589133" />
      <inertia
        ixx="0.000119094117236868"
        ixy="1.44019124754279E-10"
        ixz="-2.20407452345011E-07"
        iyy="0.000279261953137755"
        iyz="-1.69484268438423E-07"
        izz="0.000242859744665875" />
    </inertial>
    <visual>
      <origin
        xyz="0 0 0"
        rpy="0 0 0" />
      <geometry>
        <mesh
          filename="package://bparm_5_1_description/meshes/link1.STL" />
      </geometry>
      <material
        name="">
        <color
          rgba="1 1 1 1" />
      </material>
    </visual>
    <collision>
      <origin
        xyz="0 0 0"
        rpy="0 0 0" />
      <geometry>
        <mesh
          filename="package://bparm_5_1_description/meshes/link1.STL" />
      </geometry>
    </collision>
  </link>
  <joint
    name="joint1"
    type="revolute">
    <origin
      xyz="0 0 0.0614999999999997"
      rpy="1.5707963267949 0 1.57079630573043" />
    <parent
      link="base_link" />
    <child
      link="link1" />
    <axis
      xyz="0 -1 0" />
    <limit
      lower="-1.8"
      upper="1.8"
      effort="1"
      velocity="1" />
  </joint>
  <link
    name="link2">
    <inertial>
      <origin
        xyz="-0.00682457800243758 -7.51609885440985E-10 3.29678837007741E-08"
        rpy="0 0 0" />
      <mass
        value="0.0145153852066725" />
      <inertia
        ixx="1.87202662285493E-06"
        ixy="-4.29603036576602E-14"
        ixz="-9.92179608420231E-15"
        iyy="1.29106359215905E-06"
        iyz="-3.47348383075651E-13"
        izz="1.23235197527979E-06" />
    </inertial>
    <visual>
      <origin
        xyz="0 0 0"
        rpy="0 0 0" />
      <geometry>
        <mesh
          filename="package://bparm_5_1_description/meshes/link2.STL" />
      </geometry>
      <material
        name="">
        <color
          rgba="0.776470588235294 0.756862745098039 0.737254901960784 1" />
      </material>
    </visual>
    <collision>
      <origin
        xyz="0 0 0"
        rpy="0 0 0" />
      <geometry>
        <mesh
          filename="package://bparm_5_1_description/meshes/link2.STL" />
      </geometry>
    </collision>
  </link>
  <joint
    name="joint2"
    type="revolute">
    <origin
      xyz="0 0.04 0"
      rpy="-1.57079634785937 0 -1.5707963267949" />
    <parent
      link="link1" />
    <child
      link="link2" />
    <axis
      xyz="0 0 1" />
    <limit
      lower="-1.8"
      upper="1.8"
      effort="1"
      velocity="1" />
  </joint>
  <link
    name="link3">
    <inertial>
      <origin
        xyz="-2.12079369469875E-05 0.100464889655343 -0.000408315812513715"
        rpy="0 0 0" />
      <mass
        value="0.191360304125798" />
      <inertia
        ixx="0.000620746471029824"
        ixy="4.73465457580558E-07"
        ixz="2.33932262032956E-08"
        iyy="3.89402242446652E-05"
        iyz="-1.62966617576368E-06"
        izz="0.000636034292716962" />
    </inertial>
    <visual>
      <origin
        xyz="0 0 0"
        rpy="0 0 0" />
      <geometry>
        <mesh
          filename="package://bparm_5_1_description/meshes/link3.STL" />
      </geometry>
      <material
        name="">
        <color
          rgba="1 1 1 1" />
      </material>
    </visual>
    <collision>
      <origin
        xyz="0 0 0"
        rpy="0 0 0" />
      <geometry>
        <mesh
          filename="package://bparm_5_1_description/meshes/link3.STL" />
      </geometry>
    </collision>
  </link>
  <joint
    name="joint3"
    type="revolute">
    <origin
      xyz="-0.0225398298614661 0 0"
      rpy="1.5707963267949 -1.5707963267949 0" />
    <parent
      link="link2" />
    <child
      link="link3" />
    <axis
      xyz="0 -1 0" />
    <limit
      lower="-1.8"
      upper="1.8"
      effort="1"
      velocity="1" />
  </joint>
  <link
    name="link4">
    <inertial>
      <origin
        xyz="5.4169476120941E-05 0.0711418303491069 -0.0139420842352693"
        rpy="0 0 0" />
      <mass
        value="0.165671646930781" />
      <inertia
        ixx="0.000168868249508342"
        ixy="-2.69469642449062E-08"
        ixz="4.05097447871256E-08"
        iyy="4.69717097850837E-05"
        iyz="-1.03327826883113E-06"
        izz="0.000175146940963635" />
    </inertial>
    <visual>
      <origin
        xyz="0 0 0"
        rpy="0 0 0" />
      <geometry>
        <mesh
          filename="package://bparm_5_1_description/meshes/link4.STL" />
      </geometry>
      <material
        name="">
        <color
          rgba="1 1 1 1" />
      </material>
    </visual>
    <collision>
      <origin
        xyz="0 0 0"
        rpy="0 0 0" />
      <geometry>
        <mesh
          filename="package://bparm_5_1_description/meshes/link4.STL" />
      </geometry>
    </collision>
  </link>
  <joint
    name="joint4"
    type="revolute">
    <origin
      xyz="0 0.2 -0.0190000000000045"
      rpy="0 0 0" />
    <parent
      link="link3" />
    <child
      link="link4" />
    <axis
      xyz="0 0 -1" />
    <limit
      lower="-2.35"
      upper="2.35"
      effort="1"
      velocity="1" />
  </joint>
  <link
    name="link5">
    <inertial>
      <origin
        xyz="6.80793618007547E-07 0.040464603044332 0.000591187634898072"
        rpy="0 0 0" />
      <mass
        value="0.164695579944042" />
      <inertia
        ixx="0.000192367151187575"
        ixy="-2.69244029869537E-07"
        ixz="1.70687310964095E-08"
        iyy="4.09586796976324E-05"
        iyz="1.24434581079354E-06"
        izz="0.000199970106498001" />
    </inertial>
    <visual>
      <origin
        xyz="0 0 0"
        rpy="0 0 0" />
      <geometry>
        <mesh
          filename="package://bparm_5_1_description/meshes/link5.STL" />
      </geometry>
      <material
        name="">
        <color
          rgba="1 1 1 1" />
      </material>
    </visual>
    <collision>
      <origin
        xyz="0 0 0"
        rpy="0 0 0" />
      <geometry>
        <mesh
          filename="package://bparm_5_1_description/meshes/link5.STL" />
      </geometry>
    </collision>
  </link>
  <joint
    name="joint5"
    type="revolute">
    <origin
      xyz="0 0.188 -0.014"
      rpy="0 0 0" />
    <parent
      link="link4" />
    <child
      link="link5" />
    <axis
      xyz="0 -1 0" />
    <limit
      lower="-1.8"
      upper="1.8"
      effort="1"
      velocity="1" />
  </joint>
  <link
    name="link6">
    <inertial>
      <origin
        xyz="0.0336178760368403 -0.0152798218033703 -2.9261767678368E-07"
        rpy="0 0 0" />
      <mass
        value="0.0706761356774253" />
      <inertia
        ixx="2.90112639724966E-05"
        ixy="6.50721999236753E-06"
        ixz="-4.21821952775762E-10"
        iyy="8.11759956239221E-05"
        iyz="-4.13421649699637E-10"
        izz="8.55719171336377E-05" />
    </inertial>
    <visual>
      <origin
        xyz="0 0 0"
        rpy="0 0 0" />
      <geometry>
        <mesh
          filename="package://bparm_5_1_description/meshes/link6.STL" />
      </geometry>
      <material
        name="">
        <color
          rgba="1 1 1 1" />
      </material>
    </visual>
    <collision>
      <origin
        xyz="0 0 0"
        rpy="0 0 0" />
      <geometry>
        <mesh
          filename="package://bparm_5_1_description/meshes/link6.STL" />
      </geometry>
    </collision>
  </link>
  <joint
    name="joint6"
    type="revolute">
    <origin
      xyz="0 0.122 0.0465"
      rpy="1.5708 0 1.5708" />
    <parent
      link="link5" />
    <child
      link="link6" />
    <axis
      xyz="0 -1 0" />
    <limit
      lower="-2.35"
      upper="2.35"
      effort="1"
      velocity="1" />
  </joint>
  <link
    name="linkCamera">
    <inertial>
      <origin
        xyz="-7.89823422421149E-05 8.5034083425084E-05 -0.0113644630680405"
        rpy="0 0 0" />
      <mass
        value="1.07678808685044" />
      <inertia
        ixx="0.000197188419732538"
        ixy="-1.12309543914858E-08"
        ixz="-4.1690465254123E-07"
        iyy="0.000197433047359348"
        iyz="2.96522504119722E-07"
        izz="0.000301366659761361" />
    </inertial>
    <visual>
      <origin
        xyz="0 0 0"
        rpy="0 0 0" />
      <geometry>
        <mesh
          filename="package://bparm_5_1_description/meshes/linkCamera.STL" />
      </geometry>
      <material
        name="">
        <color
          rgba="1 0.941176470588235 0.67843137254902 1" />
      </material>
    </visual>
    <collision>
      <origin
        xyz="0 0 0"
        rpy="0 0 0" />
      <geometry>
        <mesh
          filename="package://bparm_5_1_description/meshes/linkCamera.STL" />
      </geometry>
    </collision>
  </link>
  <gazebo reference="linkCamera">
    <sensor name="camera_sensor" type="camera">
      <pose>0 0 0 0 0 0</pose> <!-- relative to linkCamera -->
      <camera>
        <horizontal_fov>1.3962634</horizontal_fov> <!-- 80 degrees -->
        <image>
          <width>640</width>
          <height>480</height>
          <format>R8G8B8</format>
        </image>
        <clip>
          <near>0.1</near>
          <far>100</far>
        </clip>
      </camera>
      <always_on>true</always_on>
      <update_rate>30</update_rate>
      <visualize>true</visualize>
      <plugin name="camera_controller" filename="libgazebo_ros_camera.so">
        <ros>
          <namespace>/camera</namespace>
        </ros>
        <camera_name>camera</camera_name>
        <image_topic_name>image_raw</image_topic_name>
        <camera_info_topic_name>camera_info</camera_info_topic_name>
        <frame_name>linkCamera</frame_name>
      </plugin>
    </sensor>
  </gazebo>
  <joint
    name="jointCamera"
    type="fixed">
    <origin
      xyz="0.095 -0.028 0"
      rpy="1.5708 1.5708 0" />
    <parent
      link="link6" />
    <child
      link="linkCamera" />
    <axis
      xyz="0 0 0" />
  </joint>
  <link
    name="linkGripper">
    <inertial>
      <origin
        xyz="-0.000629194753795748 -0.0571025904165044 0.0513770429505706"
        rpy="0 0 0" />
      <mass
        value="0.113939986237523" />
      <inertia
        ixx="3.98127746222516E-05"
        ixy="-1.19188958861041E-06"
        ixz="-3.01428896460108E-07"
        iyy="4.3563309926854E-05"
        iyz="1.25186187910718E-06"
        izz="1.45864743052104E-05" />
    </inertial>
    <visual>
      <origin
        xyz="0 0 0"
        rpy="0 0 0" />
      <geometry>
        <mesh
          filename="package://bparm_5_1_description/meshes/linkGripper.STL" />
      </geometry>
      <material
        name="">
        <color
          rgba="0.752941176470588 0.752941176470588 0.752941176470588 1" />
      </material>
    </visual>
    <collision>
      <origin
        xyz="0 0 0"
        rpy="0 0 0" />
      <geometry>
        <mesh
          filename="package://bparm_5_1_description/meshes/linkGripper.STL" />
      </geometry>
    </collision>
  </link>
  <joint
    name="jointGripper"
    type="fixed">
    <origin
      xyz="0.054633 -0.11705 -0.049298"
      rpy="0 -0.0087266 3.1416" />
    <parent
      link="link6" />
    <child
      link="linkGripper" />
    <axis
      xyz="0 0 0" />
  </joint>
</robot>